{
 "cells": [
  {
   "cell_type": "markdown",
   "id": "79924323-66d1-4646-9bfa-82f8ad34d6cb",
   "metadata": {},
   "source": [
    "# Geocoding of schools dataset"
   ]
  },
  {
   "cell_type": "code",
   "execution_count": 58,
   "id": "37ef66c8-8b4d-4891-a4ed-dbd30cfcc286",
   "metadata": {},
   "outputs": [],
   "source": [
    "import pandas as pd\n",
    "import requests\n",
    "import os"
   ]
  },
  {
   "cell_type": "code",
   "execution_count": 65,
   "id": "c94442e0-2821-4975-af87-99c82459db9a",
   "metadata": {},
   "outputs": [],
   "source": [
    "GOOGLE_API_KEY = os.environ['GOOGLE_API_KEY']"
   ]
  },
  {
   "cell_type": "code",
   "execution_count": 2,
   "id": "3c2c9464-95dc-4838-83f7-32231184d565",
   "metadata": {},
   "outputs": [],
   "source": [
    "folder_path = '../data/raw'\n",
    "primary_schools = 'mainstream-schools_dublin_2019-2020.xlsx'\n",
    "secondary_schools = 'post-primary-schools-2019-2020-1.xlsx'\n",
    "special_schools = 'special-schools_dublin_2019-2020.xlsx'"
   ]
  },
  {
   "cell_type": "code",
   "execution_count": 3,
   "id": "834db0c6-c0a3-482f-b96f-86699b7aaf0b",
   "metadata": {},
   "outputs": [],
   "source": [
    "data = pd.ExcelFile(f\"{folder_path}/{primary_schools}\")"
   ]
  },
  {
   "cell_type": "code",
   "execution_count": 4,
   "id": "bfb5a6d4-8d45-45df-8efc-8162fd7d07ee",
   "metadata": {},
   "outputs": [
    {
     "data": {
      "text/plain": [
       "['Sheet1']"
      ]
     },
     "execution_count": 4,
     "metadata": {},
     "output_type": "execute_result"
    }
   ],
   "source": [
    "data.sheet_names"
   ]
  },
  {
   "cell_type": "code",
   "execution_count": 5,
   "id": "6370e5cb-c924-41e1-baf6-7f24c3e7787f",
   "metadata": {},
   "outputs": [],
   "source": [
    "df = data.parse('Sheet1')"
   ]
  },
  {
   "cell_type": "code",
   "execution_count": 6,
   "id": "94aafe68-7f87-4e72-b3c5-54648f797138",
   "metadata": {},
   "outputs": [],
   "source": [
    "def extract_lat_long_via_address(address_or_zipcode):\n",
    "    lat, lng = None, None\n",
    "    api_key = GOOGLE_API_KEY\n",
    "    base_url = \"https://maps.googleapis.com/maps/api/geocode/json\"\n",
    "    endpoint = f\"{base_url}?address={address_or_zipcode}&key={api_key}\"\n",
    "    # see how our endpoint includes our API key? Yes this is yet another reason to restrict the key\n",
    "    r = requests.get(endpoint)\n",
    "    if r.status_code not in range(200, 299):\n",
    "        return None, None\n",
    "    try:\n",
    "        '''\n",
    "        This try block incase any of our inputs are invalid. This is done instead\n",
    "        of actually writing out handlers for all kinds of responses.\n",
    "        '''\n",
    "        results = r.json()['results'][0]\n",
    "        lat = results['geometry']['location']['lat']\n",
    "        lng = results['geometry']['location']['lng']\n",
    "    except:\n",
    "        pass\n",
    "    return (lat, lng)"
   ]
  },
  {
   "cell_type": "code",
   "execution_count": 51,
   "id": "ea020986-fa21-4ed7-8e25-980bfefb5ba4",
   "metadata": {},
   "outputs": [],
   "source": [
    "df['appended_address'] = df.Eircode.fillna(df.iloc[:,1] + ' ' + df.iloc[:,2] + ', ' + df.iloc[:,3] + ', ' + df.iloc[:,4])"
   ]
  },
  {
   "cell_type": "code",
   "execution_count": null,
   "id": "2bd0e007-fce4-4ceb-8224-283755645f4e",
   "metadata": {},
   "outputs": [
    {
     "ename": "ConnectionError",
     "evalue": "('Connection aborted.', RemoteDisconnected('Remote end closed connection without response'))",
     "output_type": "error",
     "traceback": [
      "\u001b[0;31m---------------------------------------------------------------------------\u001b[0m",
      "\u001b[0;31mRemoteDisconnected\u001b[0m                        Traceback (most recent call last)",
      "File \u001b[0;32m/opt/conda/lib/python3.9/site-packages/urllib3/connectionpool.py:703\u001b[0m, in \u001b[0;36mHTTPConnectionPool.urlopen\u001b[0;34m(self, method, url, body, headers, retries, redirect, assert_same_host, timeout, pool_timeout, release_conn, chunked, body_pos, **response_kw)\u001b[0m\n\u001b[1;32m    702\u001b[0m \u001b[38;5;66;03m# Make the request on the httplib connection object.\u001b[39;00m\n\u001b[0;32m--> 703\u001b[0m httplib_response \u001b[38;5;241m=\u001b[39m \u001b[38;5;28;43mself\u001b[39;49m\u001b[38;5;241;43m.\u001b[39;49m\u001b[43m_make_request\u001b[49m\u001b[43m(\u001b[49m\n\u001b[1;32m    704\u001b[0m \u001b[43m    \u001b[49m\u001b[43mconn\u001b[49m\u001b[43m,\u001b[49m\n\u001b[1;32m    705\u001b[0m \u001b[43m    \u001b[49m\u001b[43mmethod\u001b[49m\u001b[43m,\u001b[49m\n\u001b[1;32m    706\u001b[0m \u001b[43m    \u001b[49m\u001b[43murl\u001b[49m\u001b[43m,\u001b[49m\n\u001b[1;32m    707\u001b[0m \u001b[43m    \u001b[49m\u001b[43mtimeout\u001b[49m\u001b[38;5;241;43m=\u001b[39;49m\u001b[43mtimeout_obj\u001b[49m\u001b[43m,\u001b[49m\n\u001b[1;32m    708\u001b[0m \u001b[43m    \u001b[49m\u001b[43mbody\u001b[49m\u001b[38;5;241;43m=\u001b[39;49m\u001b[43mbody\u001b[49m\u001b[43m,\u001b[49m\n\u001b[1;32m    709\u001b[0m \u001b[43m    \u001b[49m\u001b[43mheaders\u001b[49m\u001b[38;5;241;43m=\u001b[39;49m\u001b[43mheaders\u001b[49m\u001b[43m,\u001b[49m\n\u001b[1;32m    710\u001b[0m \u001b[43m    \u001b[49m\u001b[43mchunked\u001b[49m\u001b[38;5;241;43m=\u001b[39;49m\u001b[43mchunked\u001b[49m\u001b[43m,\u001b[49m\n\u001b[1;32m    711\u001b[0m \u001b[43m\u001b[49m\u001b[43m)\u001b[49m\n\u001b[1;32m    713\u001b[0m \u001b[38;5;66;03m# If we're going to release the connection in ``finally:``, then\u001b[39;00m\n\u001b[1;32m    714\u001b[0m \u001b[38;5;66;03m# the response doesn't need to know about the connection. Otherwise\u001b[39;00m\n\u001b[1;32m    715\u001b[0m \u001b[38;5;66;03m# it will also try to release it and we'll have a double-release\u001b[39;00m\n\u001b[1;32m    716\u001b[0m \u001b[38;5;66;03m# mess.\u001b[39;00m\n",
      "File \u001b[0;32m/opt/conda/lib/python3.9/site-packages/urllib3/connectionpool.py:449\u001b[0m, in \u001b[0;36mHTTPConnectionPool._make_request\u001b[0;34m(self, conn, method, url, timeout, chunked, **httplib_request_kw)\u001b[0m\n\u001b[1;32m    445\u001b[0m         \u001b[38;5;28;01mexcept\u001b[39;00m \u001b[38;5;167;01mBaseException\u001b[39;00m \u001b[38;5;28;01mas\u001b[39;00m e:\n\u001b[1;32m    446\u001b[0m             \u001b[38;5;66;03m# Remove the TypeError from the exception chain in\u001b[39;00m\n\u001b[1;32m    447\u001b[0m             \u001b[38;5;66;03m# Python 3 (including for exceptions like SystemExit).\u001b[39;00m\n\u001b[1;32m    448\u001b[0m             \u001b[38;5;66;03m# Otherwise it looks like a bug in the code.\u001b[39;00m\n\u001b[0;32m--> 449\u001b[0m             \u001b[43msix\u001b[49m\u001b[38;5;241;43m.\u001b[39;49m\u001b[43mraise_from\u001b[49m\u001b[43m(\u001b[49m\u001b[43me\u001b[49m\u001b[43m,\u001b[49m\u001b[43m \u001b[49m\u001b[38;5;28;43;01mNone\u001b[39;49;00m\u001b[43m)\u001b[49m\n\u001b[1;32m    450\u001b[0m \u001b[38;5;28;01mexcept\u001b[39;00m (SocketTimeout, BaseSSLError, SocketError) \u001b[38;5;28;01mas\u001b[39;00m e:\n",
      "File \u001b[0;32m<string>:3\u001b[0m, in \u001b[0;36mraise_from\u001b[0;34m(value, from_value)\u001b[0m\n",
      "File \u001b[0;32m/opt/conda/lib/python3.9/site-packages/urllib3/connectionpool.py:444\u001b[0m, in \u001b[0;36mHTTPConnectionPool._make_request\u001b[0;34m(self, conn, method, url, timeout, chunked, **httplib_request_kw)\u001b[0m\n\u001b[1;32m    443\u001b[0m \u001b[38;5;28;01mtry\u001b[39;00m:\n\u001b[0;32m--> 444\u001b[0m     httplib_response \u001b[38;5;241m=\u001b[39m \u001b[43mconn\u001b[49m\u001b[38;5;241;43m.\u001b[39;49m\u001b[43mgetresponse\u001b[49m\u001b[43m(\u001b[49m\u001b[43m)\u001b[49m\n\u001b[1;32m    445\u001b[0m \u001b[38;5;28;01mexcept\u001b[39;00m \u001b[38;5;167;01mBaseException\u001b[39;00m \u001b[38;5;28;01mas\u001b[39;00m e:\n\u001b[1;32m    446\u001b[0m     \u001b[38;5;66;03m# Remove the TypeError from the exception chain in\u001b[39;00m\n\u001b[1;32m    447\u001b[0m     \u001b[38;5;66;03m# Python 3 (including for exceptions like SystemExit).\u001b[39;00m\n\u001b[1;32m    448\u001b[0m     \u001b[38;5;66;03m# Otherwise it looks like a bug in the code.\u001b[39;00m\n",
      "File \u001b[0;32m/opt/conda/lib/python3.9/http/client.py:1377\u001b[0m, in \u001b[0;36mHTTPConnection.getresponse\u001b[0;34m(self)\u001b[0m\n\u001b[1;32m   1376\u001b[0m \u001b[38;5;28;01mtry\u001b[39;00m:\n\u001b[0;32m-> 1377\u001b[0m     \u001b[43mresponse\u001b[49m\u001b[38;5;241;43m.\u001b[39;49m\u001b[43mbegin\u001b[49m\u001b[43m(\u001b[49m\u001b[43m)\u001b[49m\n\u001b[1;32m   1378\u001b[0m \u001b[38;5;28;01mexcept\u001b[39;00m \u001b[38;5;167;01mConnectionError\u001b[39;00m:\n",
      "File \u001b[0;32m/opt/conda/lib/python3.9/http/client.py:320\u001b[0m, in \u001b[0;36mHTTPResponse.begin\u001b[0;34m(self)\u001b[0m\n\u001b[1;32m    319\u001b[0m \u001b[38;5;28;01mwhile\u001b[39;00m \u001b[38;5;28;01mTrue\u001b[39;00m:\n\u001b[0;32m--> 320\u001b[0m     version, status, reason \u001b[38;5;241m=\u001b[39m \u001b[38;5;28;43mself\u001b[39;49m\u001b[38;5;241;43m.\u001b[39;49m\u001b[43m_read_status\u001b[49m\u001b[43m(\u001b[49m\u001b[43m)\u001b[49m\n\u001b[1;32m    321\u001b[0m     \u001b[38;5;28;01mif\u001b[39;00m status \u001b[38;5;241m!=\u001b[39m CONTINUE:\n",
      "File \u001b[0;32m/opt/conda/lib/python3.9/http/client.py:289\u001b[0m, in \u001b[0;36mHTTPResponse._read_status\u001b[0;34m(self)\u001b[0m\n\u001b[1;32m    286\u001b[0m \u001b[38;5;28;01mif\u001b[39;00m \u001b[38;5;129;01mnot\u001b[39;00m line:\n\u001b[1;32m    287\u001b[0m     \u001b[38;5;66;03m# Presumably, the server closed the connection before\u001b[39;00m\n\u001b[1;32m    288\u001b[0m     \u001b[38;5;66;03m# sending a valid response.\u001b[39;00m\n\u001b[0;32m--> 289\u001b[0m     \u001b[38;5;28;01mraise\u001b[39;00m RemoteDisconnected(\u001b[38;5;124m\"\u001b[39m\u001b[38;5;124mRemote end closed connection without\u001b[39m\u001b[38;5;124m\"\u001b[39m\n\u001b[1;32m    290\u001b[0m                              \u001b[38;5;124m\"\u001b[39m\u001b[38;5;124m response\u001b[39m\u001b[38;5;124m\"\u001b[39m)\n\u001b[1;32m    291\u001b[0m \u001b[38;5;28;01mtry\u001b[39;00m:\n",
      "\u001b[0;31mRemoteDisconnected\u001b[0m: Remote end closed connection without response",
      "\nDuring handling of the above exception, another exception occurred:\n",
      "\u001b[0;31mProtocolError\u001b[0m                             Traceback (most recent call last)",
      "File \u001b[0;32m/opt/conda/lib/python3.9/site-packages/requests/adapters.py:489\u001b[0m, in \u001b[0;36mHTTPAdapter.send\u001b[0;34m(self, request, stream, timeout, verify, cert, proxies)\u001b[0m\n\u001b[1;32m    488\u001b[0m \u001b[38;5;28;01mif\u001b[39;00m \u001b[38;5;129;01mnot\u001b[39;00m chunked:\n\u001b[0;32m--> 489\u001b[0m     resp \u001b[38;5;241m=\u001b[39m \u001b[43mconn\u001b[49m\u001b[38;5;241;43m.\u001b[39;49m\u001b[43murlopen\u001b[49m\u001b[43m(\u001b[49m\n\u001b[1;32m    490\u001b[0m \u001b[43m        \u001b[49m\u001b[43mmethod\u001b[49m\u001b[38;5;241;43m=\u001b[39;49m\u001b[43mrequest\u001b[49m\u001b[38;5;241;43m.\u001b[39;49m\u001b[43mmethod\u001b[49m\u001b[43m,\u001b[49m\n\u001b[1;32m    491\u001b[0m \u001b[43m        \u001b[49m\u001b[43murl\u001b[49m\u001b[38;5;241;43m=\u001b[39;49m\u001b[43murl\u001b[49m\u001b[43m,\u001b[49m\n\u001b[1;32m    492\u001b[0m \u001b[43m        \u001b[49m\u001b[43mbody\u001b[49m\u001b[38;5;241;43m=\u001b[39;49m\u001b[43mrequest\u001b[49m\u001b[38;5;241;43m.\u001b[39;49m\u001b[43mbody\u001b[49m\u001b[43m,\u001b[49m\n\u001b[1;32m    493\u001b[0m \u001b[43m        \u001b[49m\u001b[43mheaders\u001b[49m\u001b[38;5;241;43m=\u001b[39;49m\u001b[43mrequest\u001b[49m\u001b[38;5;241;43m.\u001b[39;49m\u001b[43mheaders\u001b[49m\u001b[43m,\u001b[49m\n\u001b[1;32m    494\u001b[0m \u001b[43m        \u001b[49m\u001b[43mredirect\u001b[49m\u001b[38;5;241;43m=\u001b[39;49m\u001b[38;5;28;43;01mFalse\u001b[39;49;00m\u001b[43m,\u001b[49m\n\u001b[1;32m    495\u001b[0m \u001b[43m        \u001b[49m\u001b[43massert_same_host\u001b[49m\u001b[38;5;241;43m=\u001b[39;49m\u001b[38;5;28;43;01mFalse\u001b[39;49;00m\u001b[43m,\u001b[49m\n\u001b[1;32m    496\u001b[0m \u001b[43m        \u001b[49m\u001b[43mpreload_content\u001b[49m\u001b[38;5;241;43m=\u001b[39;49m\u001b[38;5;28;43;01mFalse\u001b[39;49;00m\u001b[43m,\u001b[49m\n\u001b[1;32m    497\u001b[0m \u001b[43m        \u001b[49m\u001b[43mdecode_content\u001b[49m\u001b[38;5;241;43m=\u001b[39;49m\u001b[38;5;28;43;01mFalse\u001b[39;49;00m\u001b[43m,\u001b[49m\n\u001b[1;32m    498\u001b[0m \u001b[43m        \u001b[49m\u001b[43mretries\u001b[49m\u001b[38;5;241;43m=\u001b[39;49m\u001b[38;5;28;43mself\u001b[39;49m\u001b[38;5;241;43m.\u001b[39;49m\u001b[43mmax_retries\u001b[49m\u001b[43m,\u001b[49m\n\u001b[1;32m    499\u001b[0m \u001b[43m        \u001b[49m\u001b[43mtimeout\u001b[49m\u001b[38;5;241;43m=\u001b[39;49m\u001b[43mtimeout\u001b[49m\u001b[43m,\u001b[49m\n\u001b[1;32m    500\u001b[0m \u001b[43m    \u001b[49m\u001b[43m)\u001b[49m\n\u001b[1;32m    502\u001b[0m \u001b[38;5;66;03m# Send the request.\u001b[39;00m\n\u001b[1;32m    503\u001b[0m \u001b[38;5;28;01melse\u001b[39;00m:\n",
      "File \u001b[0;32m/opt/conda/lib/python3.9/site-packages/urllib3/connectionpool.py:787\u001b[0m, in \u001b[0;36mHTTPConnectionPool.urlopen\u001b[0;34m(self, method, url, body, headers, retries, redirect, assert_same_host, timeout, pool_timeout, release_conn, chunked, body_pos, **response_kw)\u001b[0m\n\u001b[1;32m    785\u001b[0m     e \u001b[38;5;241m=\u001b[39m ProtocolError(\u001b[38;5;124m\"\u001b[39m\u001b[38;5;124mConnection aborted.\u001b[39m\u001b[38;5;124m\"\u001b[39m, e)\n\u001b[0;32m--> 787\u001b[0m retries \u001b[38;5;241m=\u001b[39m \u001b[43mretries\u001b[49m\u001b[38;5;241;43m.\u001b[39;49m\u001b[43mincrement\u001b[49m\u001b[43m(\u001b[49m\n\u001b[1;32m    788\u001b[0m \u001b[43m    \u001b[49m\u001b[43mmethod\u001b[49m\u001b[43m,\u001b[49m\u001b[43m \u001b[49m\u001b[43murl\u001b[49m\u001b[43m,\u001b[49m\u001b[43m \u001b[49m\u001b[43merror\u001b[49m\u001b[38;5;241;43m=\u001b[39;49m\u001b[43me\u001b[49m\u001b[43m,\u001b[49m\u001b[43m \u001b[49m\u001b[43m_pool\u001b[49m\u001b[38;5;241;43m=\u001b[39;49m\u001b[38;5;28;43mself\u001b[39;49m\u001b[43m,\u001b[49m\u001b[43m \u001b[49m\u001b[43m_stacktrace\u001b[49m\u001b[38;5;241;43m=\u001b[39;49m\u001b[43msys\u001b[49m\u001b[38;5;241;43m.\u001b[39;49m\u001b[43mexc_info\u001b[49m\u001b[43m(\u001b[49m\u001b[43m)\u001b[49m\u001b[43m[\u001b[49m\u001b[38;5;241;43m2\u001b[39;49m\u001b[43m]\u001b[49m\n\u001b[1;32m    789\u001b[0m \u001b[43m\u001b[49m\u001b[43m)\u001b[49m\n\u001b[1;32m    790\u001b[0m retries\u001b[38;5;241m.\u001b[39msleep()\n",
      "File \u001b[0;32m/opt/conda/lib/python3.9/site-packages/urllib3/util/retry.py:550\u001b[0m, in \u001b[0;36mRetry.increment\u001b[0;34m(self, method, url, response, error, _pool, _stacktrace)\u001b[0m\n\u001b[1;32m    549\u001b[0m \u001b[38;5;28;01mif\u001b[39;00m read \u001b[38;5;129;01mis\u001b[39;00m \u001b[38;5;28;01mFalse\u001b[39;00m \u001b[38;5;129;01mor\u001b[39;00m \u001b[38;5;129;01mnot\u001b[39;00m \u001b[38;5;28mself\u001b[39m\u001b[38;5;241m.\u001b[39m_is_method_retryable(method):\n\u001b[0;32m--> 550\u001b[0m     \u001b[38;5;28;01mraise\u001b[39;00m \u001b[43msix\u001b[49m\u001b[38;5;241;43m.\u001b[39;49m\u001b[43mreraise\u001b[49m\u001b[43m(\u001b[49m\u001b[38;5;28;43mtype\u001b[39;49m\u001b[43m(\u001b[49m\u001b[43merror\u001b[49m\u001b[43m)\u001b[49m\u001b[43m,\u001b[49m\u001b[43m \u001b[49m\u001b[43merror\u001b[49m\u001b[43m,\u001b[49m\u001b[43m \u001b[49m\u001b[43m_stacktrace\u001b[49m\u001b[43m)\u001b[49m\n\u001b[1;32m    551\u001b[0m \u001b[38;5;28;01melif\u001b[39;00m read \u001b[38;5;129;01mis\u001b[39;00m \u001b[38;5;129;01mnot\u001b[39;00m \u001b[38;5;28;01mNone\u001b[39;00m:\n",
      "File \u001b[0;32m/opt/conda/lib/python3.9/site-packages/urllib3/packages/six.py:769\u001b[0m, in \u001b[0;36mreraise\u001b[0;34m(tp, value, tb)\u001b[0m\n\u001b[1;32m    768\u001b[0m \u001b[38;5;28;01mif\u001b[39;00m value\u001b[38;5;241m.\u001b[39m__traceback__ \u001b[38;5;129;01mis\u001b[39;00m \u001b[38;5;129;01mnot\u001b[39;00m tb:\n\u001b[0;32m--> 769\u001b[0m     \u001b[38;5;28;01mraise\u001b[39;00m value\u001b[38;5;241m.\u001b[39mwith_traceback(tb)\n\u001b[1;32m    770\u001b[0m \u001b[38;5;28;01mraise\u001b[39;00m value\n",
      "File \u001b[0;32m/opt/conda/lib/python3.9/site-packages/urllib3/connectionpool.py:703\u001b[0m, in \u001b[0;36mHTTPConnectionPool.urlopen\u001b[0;34m(self, method, url, body, headers, retries, redirect, assert_same_host, timeout, pool_timeout, release_conn, chunked, body_pos, **response_kw)\u001b[0m\n\u001b[1;32m    702\u001b[0m \u001b[38;5;66;03m# Make the request on the httplib connection object.\u001b[39;00m\n\u001b[0;32m--> 703\u001b[0m httplib_response \u001b[38;5;241m=\u001b[39m \u001b[38;5;28;43mself\u001b[39;49m\u001b[38;5;241;43m.\u001b[39;49m\u001b[43m_make_request\u001b[49m\u001b[43m(\u001b[49m\n\u001b[1;32m    704\u001b[0m \u001b[43m    \u001b[49m\u001b[43mconn\u001b[49m\u001b[43m,\u001b[49m\n\u001b[1;32m    705\u001b[0m \u001b[43m    \u001b[49m\u001b[43mmethod\u001b[49m\u001b[43m,\u001b[49m\n\u001b[1;32m    706\u001b[0m \u001b[43m    \u001b[49m\u001b[43murl\u001b[49m\u001b[43m,\u001b[49m\n\u001b[1;32m    707\u001b[0m \u001b[43m    \u001b[49m\u001b[43mtimeout\u001b[49m\u001b[38;5;241;43m=\u001b[39;49m\u001b[43mtimeout_obj\u001b[49m\u001b[43m,\u001b[49m\n\u001b[1;32m    708\u001b[0m \u001b[43m    \u001b[49m\u001b[43mbody\u001b[49m\u001b[38;5;241;43m=\u001b[39;49m\u001b[43mbody\u001b[49m\u001b[43m,\u001b[49m\n\u001b[1;32m    709\u001b[0m \u001b[43m    \u001b[49m\u001b[43mheaders\u001b[49m\u001b[38;5;241;43m=\u001b[39;49m\u001b[43mheaders\u001b[49m\u001b[43m,\u001b[49m\n\u001b[1;32m    710\u001b[0m \u001b[43m    \u001b[49m\u001b[43mchunked\u001b[49m\u001b[38;5;241;43m=\u001b[39;49m\u001b[43mchunked\u001b[49m\u001b[43m,\u001b[49m\n\u001b[1;32m    711\u001b[0m \u001b[43m\u001b[49m\u001b[43m)\u001b[49m\n\u001b[1;32m    713\u001b[0m \u001b[38;5;66;03m# If we're going to release the connection in ``finally:``, then\u001b[39;00m\n\u001b[1;32m    714\u001b[0m \u001b[38;5;66;03m# the response doesn't need to know about the connection. Otherwise\u001b[39;00m\n\u001b[1;32m    715\u001b[0m \u001b[38;5;66;03m# it will also try to release it and we'll have a double-release\u001b[39;00m\n\u001b[1;32m    716\u001b[0m \u001b[38;5;66;03m# mess.\u001b[39;00m\n",
      "File \u001b[0;32m/opt/conda/lib/python3.9/site-packages/urllib3/connectionpool.py:449\u001b[0m, in \u001b[0;36mHTTPConnectionPool._make_request\u001b[0;34m(self, conn, method, url, timeout, chunked, **httplib_request_kw)\u001b[0m\n\u001b[1;32m    445\u001b[0m         \u001b[38;5;28;01mexcept\u001b[39;00m \u001b[38;5;167;01mBaseException\u001b[39;00m \u001b[38;5;28;01mas\u001b[39;00m e:\n\u001b[1;32m    446\u001b[0m             \u001b[38;5;66;03m# Remove the TypeError from the exception chain in\u001b[39;00m\n\u001b[1;32m    447\u001b[0m             \u001b[38;5;66;03m# Python 3 (including for exceptions like SystemExit).\u001b[39;00m\n\u001b[1;32m    448\u001b[0m             \u001b[38;5;66;03m# Otherwise it looks like a bug in the code.\u001b[39;00m\n\u001b[0;32m--> 449\u001b[0m             \u001b[43msix\u001b[49m\u001b[38;5;241;43m.\u001b[39;49m\u001b[43mraise_from\u001b[49m\u001b[43m(\u001b[49m\u001b[43me\u001b[49m\u001b[43m,\u001b[49m\u001b[43m \u001b[49m\u001b[38;5;28;43;01mNone\u001b[39;49;00m\u001b[43m)\u001b[49m\n\u001b[1;32m    450\u001b[0m \u001b[38;5;28;01mexcept\u001b[39;00m (SocketTimeout, BaseSSLError, SocketError) \u001b[38;5;28;01mas\u001b[39;00m e:\n",
      "File \u001b[0;32m<string>:3\u001b[0m, in \u001b[0;36mraise_from\u001b[0;34m(value, from_value)\u001b[0m\n",
      "File \u001b[0;32m/opt/conda/lib/python3.9/site-packages/urllib3/connectionpool.py:444\u001b[0m, in \u001b[0;36mHTTPConnectionPool._make_request\u001b[0;34m(self, conn, method, url, timeout, chunked, **httplib_request_kw)\u001b[0m\n\u001b[1;32m    443\u001b[0m \u001b[38;5;28;01mtry\u001b[39;00m:\n\u001b[0;32m--> 444\u001b[0m     httplib_response \u001b[38;5;241m=\u001b[39m \u001b[43mconn\u001b[49m\u001b[38;5;241;43m.\u001b[39;49m\u001b[43mgetresponse\u001b[49m\u001b[43m(\u001b[49m\u001b[43m)\u001b[49m\n\u001b[1;32m    445\u001b[0m \u001b[38;5;28;01mexcept\u001b[39;00m \u001b[38;5;167;01mBaseException\u001b[39;00m \u001b[38;5;28;01mas\u001b[39;00m e:\n\u001b[1;32m    446\u001b[0m     \u001b[38;5;66;03m# Remove the TypeError from the exception chain in\u001b[39;00m\n\u001b[1;32m    447\u001b[0m     \u001b[38;5;66;03m# Python 3 (including for exceptions like SystemExit).\u001b[39;00m\n\u001b[1;32m    448\u001b[0m     \u001b[38;5;66;03m# Otherwise it looks like a bug in the code.\u001b[39;00m\n",
      "File \u001b[0;32m/opt/conda/lib/python3.9/http/client.py:1377\u001b[0m, in \u001b[0;36mHTTPConnection.getresponse\u001b[0;34m(self)\u001b[0m\n\u001b[1;32m   1376\u001b[0m \u001b[38;5;28;01mtry\u001b[39;00m:\n\u001b[0;32m-> 1377\u001b[0m     \u001b[43mresponse\u001b[49m\u001b[38;5;241;43m.\u001b[39;49m\u001b[43mbegin\u001b[49m\u001b[43m(\u001b[49m\u001b[43m)\u001b[49m\n\u001b[1;32m   1378\u001b[0m \u001b[38;5;28;01mexcept\u001b[39;00m \u001b[38;5;167;01mConnectionError\u001b[39;00m:\n",
      "File \u001b[0;32m/opt/conda/lib/python3.9/http/client.py:320\u001b[0m, in \u001b[0;36mHTTPResponse.begin\u001b[0;34m(self)\u001b[0m\n\u001b[1;32m    319\u001b[0m \u001b[38;5;28;01mwhile\u001b[39;00m \u001b[38;5;28;01mTrue\u001b[39;00m:\n\u001b[0;32m--> 320\u001b[0m     version, status, reason \u001b[38;5;241m=\u001b[39m \u001b[38;5;28;43mself\u001b[39;49m\u001b[38;5;241;43m.\u001b[39;49m\u001b[43m_read_status\u001b[49m\u001b[43m(\u001b[49m\u001b[43m)\u001b[49m\n\u001b[1;32m    321\u001b[0m     \u001b[38;5;28;01mif\u001b[39;00m status \u001b[38;5;241m!=\u001b[39m CONTINUE:\n",
      "File \u001b[0;32m/opt/conda/lib/python3.9/http/client.py:289\u001b[0m, in \u001b[0;36mHTTPResponse._read_status\u001b[0;34m(self)\u001b[0m\n\u001b[1;32m    286\u001b[0m \u001b[38;5;28;01mif\u001b[39;00m \u001b[38;5;129;01mnot\u001b[39;00m line:\n\u001b[1;32m    287\u001b[0m     \u001b[38;5;66;03m# Presumably, the server closed the connection before\u001b[39;00m\n\u001b[1;32m    288\u001b[0m     \u001b[38;5;66;03m# sending a valid response.\u001b[39;00m\n\u001b[0;32m--> 289\u001b[0m     \u001b[38;5;28;01mraise\u001b[39;00m RemoteDisconnected(\u001b[38;5;124m\"\u001b[39m\u001b[38;5;124mRemote end closed connection without\u001b[39m\u001b[38;5;124m\"\u001b[39m\n\u001b[1;32m    290\u001b[0m                              \u001b[38;5;124m\"\u001b[39m\u001b[38;5;124m response\u001b[39m\u001b[38;5;124m\"\u001b[39m)\n\u001b[1;32m    291\u001b[0m \u001b[38;5;28;01mtry\u001b[39;00m:\n",
      "\u001b[0;31mProtocolError\u001b[0m: ('Connection aborted.', RemoteDisconnected('Remote end closed connection without response'))",
      "\nDuring handling of the above exception, another exception occurred:\n",
      "\u001b[0;31mConnectionError\u001b[0m                           Traceback (most recent call last)",
      "Cell \u001b[0;32mIn [66], line 1\u001b[0m\n\u001b[0;32m----> 1\u001b[0m df[\u001b[38;5;124m'\u001b[39m\u001b[38;5;124mlat_long\u001b[39m\u001b[38;5;124m'\u001b[39m] \u001b[38;5;241m=\u001b[39m \u001b[43mdf\u001b[49m\u001b[38;5;241;43m.\u001b[39;49m\u001b[43mapply\u001b[49m\u001b[43m \u001b[49m\u001b[43m(\u001b[49m\u001b[38;5;28;43;01mlambda\u001b[39;49;00m\u001b[43m \u001b[49m\u001b[43mrow\u001b[49m\u001b[43m:\u001b[49m\u001b[43m \u001b[49m\u001b[43mextract_lat_long_via_address\u001b[49m\u001b[43m(\u001b[49m\u001b[43mrow\u001b[49m\u001b[38;5;241;43m.\u001b[39;49m\u001b[43mappended_address\u001b[49m\u001b[43m)\u001b[49m\u001b[43m,\u001b[49m\u001b[43m \u001b[49m\u001b[43maxis\u001b[49m\u001b[38;5;241;43m=\u001b[39;49m\u001b[38;5;241;43m1\u001b[39;49m\u001b[43m)\u001b[49m\n",
      "File \u001b[0;32m/opt/conda/lib/python3.9/site-packages/pandas/core/frame.py:9558\u001b[0m, in \u001b[0;36mDataFrame.apply\u001b[0;34m(self, func, axis, raw, result_type, args, **kwargs)\u001b[0m\n\u001b[1;32m   9547\u001b[0m \u001b[38;5;28;01mfrom\u001b[39;00m \u001b[38;5;21;01mpandas\u001b[39;00m\u001b[38;5;21;01m.\u001b[39;00m\u001b[38;5;21;01mcore\u001b[39;00m\u001b[38;5;21;01m.\u001b[39;00m\u001b[38;5;21;01mapply\u001b[39;00m \u001b[38;5;28;01mimport\u001b[39;00m frame_apply\n\u001b[1;32m   9549\u001b[0m op \u001b[38;5;241m=\u001b[39m frame_apply(\n\u001b[1;32m   9550\u001b[0m     \u001b[38;5;28mself\u001b[39m,\n\u001b[1;32m   9551\u001b[0m     func\u001b[38;5;241m=\u001b[39mfunc,\n\u001b[0;32m   (...)\u001b[0m\n\u001b[1;32m   9556\u001b[0m     kwargs\u001b[38;5;241m=\u001b[39mkwargs,\n\u001b[1;32m   9557\u001b[0m )\n\u001b[0;32m-> 9558\u001b[0m \u001b[38;5;28;01mreturn\u001b[39;00m \u001b[43mop\u001b[49m\u001b[38;5;241;43m.\u001b[39;49m\u001b[43mapply\u001b[49m\u001b[43m(\u001b[49m\u001b[43m)\u001b[49m\u001b[38;5;241m.\u001b[39m__finalize__(\u001b[38;5;28mself\u001b[39m, method\u001b[38;5;241m=\u001b[39m\u001b[38;5;124m\"\u001b[39m\u001b[38;5;124mapply\u001b[39m\u001b[38;5;124m\"\u001b[39m)\n",
      "File \u001b[0;32m/opt/conda/lib/python3.9/site-packages/pandas/core/apply.py:741\u001b[0m, in \u001b[0;36mFrameApply.apply\u001b[0;34m(self)\u001b[0m\n\u001b[1;32m    738\u001b[0m \u001b[38;5;28;01melif\u001b[39;00m \u001b[38;5;28mself\u001b[39m\u001b[38;5;241m.\u001b[39mraw:\n\u001b[1;32m    739\u001b[0m     \u001b[38;5;28;01mreturn\u001b[39;00m \u001b[38;5;28mself\u001b[39m\u001b[38;5;241m.\u001b[39mapply_raw()\n\u001b[0;32m--> 741\u001b[0m \u001b[38;5;28;01mreturn\u001b[39;00m \u001b[38;5;28;43mself\u001b[39;49m\u001b[38;5;241;43m.\u001b[39;49m\u001b[43mapply_standard\u001b[49m\u001b[43m(\u001b[49m\u001b[43m)\u001b[49m\n",
      "File \u001b[0;32m/opt/conda/lib/python3.9/site-packages/pandas/core/apply.py:868\u001b[0m, in \u001b[0;36mFrameApply.apply_standard\u001b[0;34m(self)\u001b[0m\n\u001b[1;32m    867\u001b[0m \u001b[38;5;28;01mdef\u001b[39;00m \u001b[38;5;21mapply_standard\u001b[39m(\u001b[38;5;28mself\u001b[39m):\n\u001b[0;32m--> 868\u001b[0m     results, res_index \u001b[38;5;241m=\u001b[39m \u001b[38;5;28;43mself\u001b[39;49m\u001b[38;5;241;43m.\u001b[39;49m\u001b[43mapply_series_generator\u001b[49m\u001b[43m(\u001b[49m\u001b[43m)\u001b[49m\n\u001b[1;32m    870\u001b[0m     \u001b[38;5;66;03m# wrap results\u001b[39;00m\n\u001b[1;32m    871\u001b[0m     \u001b[38;5;28;01mreturn\u001b[39;00m \u001b[38;5;28mself\u001b[39m\u001b[38;5;241m.\u001b[39mwrap_results(results, res_index)\n",
      "File \u001b[0;32m/opt/conda/lib/python3.9/site-packages/pandas/core/apply.py:884\u001b[0m, in \u001b[0;36mFrameApply.apply_series_generator\u001b[0;34m(self)\u001b[0m\n\u001b[1;32m    881\u001b[0m \u001b[38;5;28;01mwith\u001b[39;00m option_context(\u001b[38;5;124m\"\u001b[39m\u001b[38;5;124mmode.chained_assignment\u001b[39m\u001b[38;5;124m\"\u001b[39m, \u001b[38;5;28;01mNone\u001b[39;00m):\n\u001b[1;32m    882\u001b[0m     \u001b[38;5;28;01mfor\u001b[39;00m i, v \u001b[38;5;129;01min\u001b[39;00m \u001b[38;5;28menumerate\u001b[39m(series_gen):\n\u001b[1;32m    883\u001b[0m         \u001b[38;5;66;03m# ignore SettingWithCopy here in case the user mutates\u001b[39;00m\n\u001b[0;32m--> 884\u001b[0m         results[i] \u001b[38;5;241m=\u001b[39m \u001b[38;5;28;43mself\u001b[39;49m\u001b[38;5;241;43m.\u001b[39;49m\u001b[43mf\u001b[49m\u001b[43m(\u001b[49m\u001b[43mv\u001b[49m\u001b[43m)\u001b[49m\n\u001b[1;32m    885\u001b[0m         \u001b[38;5;28;01mif\u001b[39;00m \u001b[38;5;28misinstance\u001b[39m(results[i], ABCSeries):\n\u001b[1;32m    886\u001b[0m             \u001b[38;5;66;03m# If we have a view on v, we need to make a copy because\u001b[39;00m\n\u001b[1;32m    887\u001b[0m             \u001b[38;5;66;03m#  series_generator will swap out the underlying data\u001b[39;00m\n\u001b[1;32m    888\u001b[0m             results[i] \u001b[38;5;241m=\u001b[39m results[i]\u001b[38;5;241m.\u001b[39mcopy(deep\u001b[38;5;241m=\u001b[39m\u001b[38;5;28;01mFalse\u001b[39;00m)\n",
      "Cell \u001b[0;32mIn [66], line 1\u001b[0m, in \u001b[0;36m<lambda>\u001b[0;34m(row)\u001b[0m\n\u001b[0;32m----> 1\u001b[0m df[\u001b[38;5;124m'\u001b[39m\u001b[38;5;124mlat_long\u001b[39m\u001b[38;5;124m'\u001b[39m] \u001b[38;5;241m=\u001b[39m df\u001b[38;5;241m.\u001b[39mapply (\u001b[38;5;28;01mlambda\u001b[39;00m row: \u001b[43mextract_lat_long_via_address\u001b[49m\u001b[43m(\u001b[49m\u001b[43mrow\u001b[49m\u001b[38;5;241;43m.\u001b[39;49m\u001b[43mappended_address\u001b[49m\u001b[43m)\u001b[49m, axis\u001b[38;5;241m=\u001b[39m\u001b[38;5;241m1\u001b[39m)\n",
      "Cell \u001b[0;32mIn [6], line 7\u001b[0m, in \u001b[0;36mextract_lat_long_via_address\u001b[0;34m(address_or_zipcode)\u001b[0m\n\u001b[1;32m      5\u001b[0m endpoint \u001b[38;5;241m=\u001b[39m \u001b[38;5;124mf\u001b[39m\u001b[38;5;124m\"\u001b[39m\u001b[38;5;132;01m{\u001b[39;00mbase_url\u001b[38;5;132;01m}\u001b[39;00m\u001b[38;5;124m?address=\u001b[39m\u001b[38;5;132;01m{\u001b[39;00maddress_or_zipcode\u001b[38;5;132;01m}\u001b[39;00m\u001b[38;5;124m&key=\u001b[39m\u001b[38;5;132;01m{\u001b[39;00mapi_key\u001b[38;5;132;01m}\u001b[39;00m\u001b[38;5;124m\"\u001b[39m\n\u001b[1;32m      6\u001b[0m \u001b[38;5;66;03m# see how our endpoint includes our API key? Yes this is yet another reason to restrict the key\u001b[39;00m\n\u001b[0;32m----> 7\u001b[0m r \u001b[38;5;241m=\u001b[39m \u001b[43mrequests\u001b[49m\u001b[38;5;241;43m.\u001b[39;49m\u001b[43mget\u001b[49m\u001b[43m(\u001b[49m\u001b[43mendpoint\u001b[49m\u001b[43m)\u001b[49m\n\u001b[1;32m      8\u001b[0m \u001b[38;5;28;01mif\u001b[39;00m r\u001b[38;5;241m.\u001b[39mstatus_code \u001b[38;5;129;01mnot\u001b[39;00m \u001b[38;5;129;01min\u001b[39;00m \u001b[38;5;28mrange\u001b[39m(\u001b[38;5;241m200\u001b[39m, \u001b[38;5;241m299\u001b[39m):\n\u001b[1;32m      9\u001b[0m     \u001b[38;5;28;01mreturn\u001b[39;00m \u001b[38;5;28;01mNone\u001b[39;00m, \u001b[38;5;28;01mNone\u001b[39;00m\n",
      "File \u001b[0;32m/opt/conda/lib/python3.9/site-packages/requests/api.py:73\u001b[0m, in \u001b[0;36mget\u001b[0;34m(url, params, **kwargs)\u001b[0m\n\u001b[1;32m     62\u001b[0m \u001b[38;5;28;01mdef\u001b[39;00m \u001b[38;5;21mget\u001b[39m(url, params\u001b[38;5;241m=\u001b[39m\u001b[38;5;28;01mNone\u001b[39;00m, \u001b[38;5;241m*\u001b[39m\u001b[38;5;241m*\u001b[39mkwargs):\n\u001b[1;32m     63\u001b[0m     \u001b[38;5;124mr\u001b[39m\u001b[38;5;124;03m\"\"\"Sends a GET request.\u001b[39;00m\n\u001b[1;32m     64\u001b[0m \n\u001b[1;32m     65\u001b[0m \u001b[38;5;124;03m    :param url: URL for the new :class:`Request` object.\u001b[39;00m\n\u001b[0;32m   (...)\u001b[0m\n\u001b[1;32m     70\u001b[0m \u001b[38;5;124;03m    :rtype: requests.Response\u001b[39;00m\n\u001b[1;32m     71\u001b[0m \u001b[38;5;124;03m    \"\"\"\u001b[39;00m\n\u001b[0;32m---> 73\u001b[0m     \u001b[38;5;28;01mreturn\u001b[39;00m \u001b[43mrequest\u001b[49m\u001b[43m(\u001b[49m\u001b[38;5;124;43m\"\u001b[39;49m\u001b[38;5;124;43mget\u001b[39;49m\u001b[38;5;124;43m\"\u001b[39;49m\u001b[43m,\u001b[49m\u001b[43m \u001b[49m\u001b[43murl\u001b[49m\u001b[43m,\u001b[49m\u001b[43m \u001b[49m\u001b[43mparams\u001b[49m\u001b[38;5;241;43m=\u001b[39;49m\u001b[43mparams\u001b[49m\u001b[43m,\u001b[49m\u001b[43m \u001b[49m\u001b[38;5;241;43m*\u001b[39;49m\u001b[38;5;241;43m*\u001b[39;49m\u001b[43mkwargs\u001b[49m\u001b[43m)\u001b[49m\n",
      "File \u001b[0;32m/opt/conda/lib/python3.9/site-packages/requests/api.py:59\u001b[0m, in \u001b[0;36mrequest\u001b[0;34m(method, url, **kwargs)\u001b[0m\n\u001b[1;32m     55\u001b[0m \u001b[38;5;66;03m# By using the 'with' statement we are sure the session is closed, thus we\u001b[39;00m\n\u001b[1;32m     56\u001b[0m \u001b[38;5;66;03m# avoid leaving sockets open which can trigger a ResourceWarning in some\u001b[39;00m\n\u001b[1;32m     57\u001b[0m \u001b[38;5;66;03m# cases, and look like a memory leak in others.\u001b[39;00m\n\u001b[1;32m     58\u001b[0m \u001b[38;5;28;01mwith\u001b[39;00m sessions\u001b[38;5;241m.\u001b[39mSession() \u001b[38;5;28;01mas\u001b[39;00m session:\n\u001b[0;32m---> 59\u001b[0m     \u001b[38;5;28;01mreturn\u001b[39;00m \u001b[43msession\u001b[49m\u001b[38;5;241;43m.\u001b[39;49m\u001b[43mrequest\u001b[49m\u001b[43m(\u001b[49m\u001b[43mmethod\u001b[49m\u001b[38;5;241;43m=\u001b[39;49m\u001b[43mmethod\u001b[49m\u001b[43m,\u001b[49m\u001b[43m \u001b[49m\u001b[43murl\u001b[49m\u001b[38;5;241;43m=\u001b[39;49m\u001b[43murl\u001b[49m\u001b[43m,\u001b[49m\u001b[43m \u001b[49m\u001b[38;5;241;43m*\u001b[39;49m\u001b[38;5;241;43m*\u001b[39;49m\u001b[43mkwargs\u001b[49m\u001b[43m)\u001b[49m\n",
      "File \u001b[0;32m/opt/conda/lib/python3.9/site-packages/requests/sessions.py:587\u001b[0m, in \u001b[0;36mSession.request\u001b[0;34m(self, method, url, params, data, headers, cookies, files, auth, timeout, allow_redirects, proxies, hooks, stream, verify, cert, json)\u001b[0m\n\u001b[1;32m    582\u001b[0m send_kwargs \u001b[38;5;241m=\u001b[39m {\n\u001b[1;32m    583\u001b[0m     \u001b[38;5;124m\"\u001b[39m\u001b[38;5;124mtimeout\u001b[39m\u001b[38;5;124m\"\u001b[39m: timeout,\n\u001b[1;32m    584\u001b[0m     \u001b[38;5;124m\"\u001b[39m\u001b[38;5;124mallow_redirects\u001b[39m\u001b[38;5;124m\"\u001b[39m: allow_redirects,\n\u001b[1;32m    585\u001b[0m }\n\u001b[1;32m    586\u001b[0m send_kwargs\u001b[38;5;241m.\u001b[39mupdate(settings)\n\u001b[0;32m--> 587\u001b[0m resp \u001b[38;5;241m=\u001b[39m \u001b[38;5;28;43mself\u001b[39;49m\u001b[38;5;241;43m.\u001b[39;49m\u001b[43msend\u001b[49m\u001b[43m(\u001b[49m\u001b[43mprep\u001b[49m\u001b[43m,\u001b[49m\u001b[43m \u001b[49m\u001b[38;5;241;43m*\u001b[39;49m\u001b[38;5;241;43m*\u001b[39;49m\u001b[43msend_kwargs\u001b[49m\u001b[43m)\u001b[49m\n\u001b[1;32m    589\u001b[0m \u001b[38;5;28;01mreturn\u001b[39;00m resp\n",
      "File \u001b[0;32m/opt/conda/lib/python3.9/site-packages/requests/sessions.py:701\u001b[0m, in \u001b[0;36mSession.send\u001b[0;34m(self, request, **kwargs)\u001b[0m\n\u001b[1;32m    698\u001b[0m start \u001b[38;5;241m=\u001b[39m preferred_clock()\n\u001b[1;32m    700\u001b[0m \u001b[38;5;66;03m# Send the request\u001b[39;00m\n\u001b[0;32m--> 701\u001b[0m r \u001b[38;5;241m=\u001b[39m \u001b[43madapter\u001b[49m\u001b[38;5;241;43m.\u001b[39;49m\u001b[43msend\u001b[49m\u001b[43m(\u001b[49m\u001b[43mrequest\u001b[49m\u001b[43m,\u001b[49m\u001b[43m \u001b[49m\u001b[38;5;241;43m*\u001b[39;49m\u001b[38;5;241;43m*\u001b[39;49m\u001b[43mkwargs\u001b[49m\u001b[43m)\u001b[49m\n\u001b[1;32m    703\u001b[0m \u001b[38;5;66;03m# Total elapsed time of the request (approximately)\u001b[39;00m\n\u001b[1;32m    704\u001b[0m elapsed \u001b[38;5;241m=\u001b[39m preferred_clock() \u001b[38;5;241m-\u001b[39m start\n",
      "File \u001b[0;32m/opt/conda/lib/python3.9/site-packages/requests/adapters.py:547\u001b[0m, in \u001b[0;36mHTTPAdapter.send\u001b[0;34m(self, request, stream, timeout, verify, cert, proxies)\u001b[0m\n\u001b[1;32m    544\u001b[0m             \u001b[38;5;28;01mraise\u001b[39;00m\n\u001b[1;32m    546\u001b[0m \u001b[38;5;28;01mexcept\u001b[39;00m (ProtocolError, \u001b[38;5;167;01mOSError\u001b[39;00m) \u001b[38;5;28;01mas\u001b[39;00m err:\n\u001b[0;32m--> 547\u001b[0m     \u001b[38;5;28;01mraise\u001b[39;00m \u001b[38;5;167;01mConnectionError\u001b[39;00m(err, request\u001b[38;5;241m=\u001b[39mrequest)\n\u001b[1;32m    549\u001b[0m \u001b[38;5;28;01mexcept\u001b[39;00m MaxRetryError \u001b[38;5;28;01mas\u001b[39;00m e:\n\u001b[1;32m    550\u001b[0m     \u001b[38;5;28;01mif\u001b[39;00m \u001b[38;5;28misinstance\u001b[39m(e\u001b[38;5;241m.\u001b[39mreason, ConnectTimeoutError):\n\u001b[1;32m    551\u001b[0m         \u001b[38;5;66;03m# TODO: Remove this in 3.0.0: see #2811\u001b[39;00m\n",
      "\u001b[0;31mConnectionError\u001b[0m: ('Connection aborted.', RemoteDisconnected('Remote end closed connection without response'))"
     ]
    }
   ],
   "source": [
    "df['lat_long'] = df.apply (lambda row: extract_lat_long_via_address(row.appended_address), axis=1)"
   ]
  }
 ],
 "metadata": {
  "kernelspec": {
   "display_name": "Python 3 (ipykernel)",
   "language": "python",
   "name": "python3"
  },
  "language_info": {
   "codemirror_mode": {
    "name": "ipython",
    "version": 3
   },
   "file_extension": ".py",
   "mimetype": "text/x-python",
   "name": "python",
   "nbconvert_exporter": "python",
   "pygments_lexer": "ipython3",
   "version": "3.9.13"
  }
 },
 "nbformat": 4,
 "nbformat_minor": 5
}
